Workbook

Sheet Info
A1: ady-kbd AI Language Testing Tool
B3: What this test measures | C3: Bu test neyi ölçüyor | D3: Что измеряет этот тест
B4: This test does not measure translation quality, but Adyghe conversational competence. Every question is a request expressed in Adyghe. What is judged is whether the tool understood this request and attempted to meet it. Questions four and five contain a translation task, but what is measured is not the accuracy of the translation, but whether the request was understood: even a wrong translation is still a translation, and shows that the request was understood. Returning a Turkish answer to a Turkish paragraph would mean the request was not understood. | C4: Bu test çeviri kalitesini değil, Adıgece sohbet yetkinliğini ölçer. Her soru Adıgece ifade edilmiş bir istektir. Yargılanan şey, aracın bu isteği anlayıp anlamadığı ve karşılamaya çalışıp çalışmadığıdır. Dördüncü ve beşinci sorularda bir çeviri görevi vardır, ama ölçülen çevirinin doğruluğu değil, isteğin anlaşılmasıdır: yanlış çeviri de bir çeviridir ve isteğin anlaşıldığını gösterir. Türkçe bir paragraf verildiğinde Türkçe yanıt dönmesi, isteğin anlaşılmadığı anlamına gelirdi. | D4: Этот тест измеряет не качество перевода, а разговорную компетентность на адыгейском языке. Каждый вопрос — это просьба, выраженная на адыгейском. Оценивается то, понял ли инструмент эту просьбу и попытался ли её выполнить. В четвёртом и пятом вопросах есть задача перевода, но измеряется не точность перевода, а понимание просьбы: даже неверный перевод остаётся переводом и показывает, что просьба была понята. Если на турецкий абзац был бы дан турецкий ответ, это означало бы, что просьба не была понята.
B6: Metadata | C6: Künye | D6: Метаданные
A7: Test / Round Test / Tur Тест / Раунд | B7: Test 1 (round1)
A8: Generated (UTC) Üretildi (UTC) Создано (UTC) | B8: 2026-09-17 11:34:05
A9: Source files Kaynak dosyalar Исходные файлы | B9: Test1-AI-Tool1-Result.txt, Test1-AI-Tool2-Result.txt, Test1-AI-Tool3-Result.txt, Test1-AI-Tool4-Result.txt, Test1-AI-Tool5-Result.txt
A10: Tool version Araç sürümü Версия инструмента | B10: ady-kbd AI Language Testing Tool 1.0.0
A11: Evaluators Değerlendiriciler Оценщики | B11: Mehmet Uğur Nemlioğlu, Dr. Saida Abregova Nemlioğlu
A12: Evaluation method Değerlendirme yöntemi Метод оценки | B12: Consensus: both evaluators read and discuss together, and record one agreed judgement Uzlaşı: ikisi birlikte okur, tartışır, tek hüküm kaydeder Консенсус: оба оценщика читают и обсуждают вместе и записывают одно согласованное решение
A13: Evaluation date (fill in) Değerlendirme tarihi (doldurun) Дата оценки (заполните) | B13: 46282.971
A14: Total responses Toplam yanıt Всего ответов | B14: 35
B16: Decision table | C16: Karar tablosu | D16: Таблица решений
A17: Code | B17: Question | C17: Soru | D17: Вопрос
A18: FRM: form / biçim / форма | B18: Is the right word chosen, but its affix or inflection wrong? | C18: Doğru sözcük seçilmiş ama eki ya da çekimi mi yanlış? | D18: Слово выбрано правильно, но неверен его аффикс или словоизменение?
A19: CHO: choice / seçim / выбор | B19: Is the word well formed, but the wrong word for the intended meaning? | C19: Sözcük doğru kurulmuş ama anlam için yanlış sözcük mü seçilmiş? | D19: Слово образовано правильно, но по смыслу выбрано не то слово?
A20: MIX: mixing / karışma / смешение | B20: Is the word taken from another language and left in that language's own form? The contact language is recorded as well. | C20: Sözcük başka bir dilden, o dilin kendi biçimiyle olduğu gibi mi alınmış? Kaynak dil ayrıca kaydedilir. | D20: Слово взято из другого языка и оставлено в его собственной форме? Язык-источник записывается отдельно.
A21: INV: invented / uydurma / выдуманное | B21: Even if the root and affixes are familiar, is this a combination the language does not use? | C21: Kök ve ekler tanıdık olsa bile, bu birleşimi dil kullanmıyor mu? | D21: Даже если корень и аффиксы знакомы, такое сочетание в языке не используется?
A22: TRM: term / terim / термин | B22: Is the word an established loan, adapted to the language, used where a recognised native term exists? This is not an error. | C22: Sözcük, dile uyarlanmış yerleşik bir alıntı ama kabul görmüş yerli bir karşılığı var mı? Hata değildir. | D22: Слово — устоявшееся заимствование, приспособленное к языку, но есть признанный местный термин? Это не ошибка.
B23: Each word is counted under exactly one code. Read the table top to bottom; the code of the first row that answers "yes" is that word's code. Counting a word under two categories at once corrupts both the correct-word count and the contact-language total. | C23: Her sözcük yalnızca bir koda sayılır. Tabloyu yukarıdan aşağıya okuyun; ilk "evet" yanıtını veren satırın kodu o sözcüğün kodudur. Bir sözcüğü iki kategoriye birden saymak, doğru sözcük sayısını ve temas dili toplamını bozar. | D23: Каждое слово засчитывается только по одному коду. Читайте таблицу сверху вниз; код той строки, на которую первым получен ответ «да», и есть код этого слова. Если засчитать слово сразу в две категории, это испортит и подсчёт правильных слов, и сумму языков контаката.
B24: A practical way to tell these three apart: try writing the word correctly. If you can write a proper form of the same word, it is FRM; if you can, but what you write is a different word, it is CHO; if there is no correct form to write, it is INV. | C24: Bu üçünü ayırmanın pratik yolu: sözcüğün doğrusunu yazmayı dene. Aynı sözcüğün düzgün hâlini yazabiliyorsan FRM; yazabiliyorsun ama yazdığın başka bir sözcükse CHO; yazacak doğru bir hâl yoksa INV. | D24: Практический способ различить эти три: попробуйте написать слово правильно. Если вы можете написать правильную форму того же слова — это FRM; если можете, но написанное — другое слово, это CHO; если правильной формы не существует — это INV.
B25: The boundary between MIX and TRM is adaptation. A word left in the source language's form is MIX; a word adapted to this language's morphology and part of its lexicon is TRM -- and TRM is not an error. | C25: MIX ile TRM arasındaki ayrım uyarlamadır. Sözcük kaynak dilin biçiminde duruyorsa MIX; dilin biçimbilgisine uyarlanmış ve söz varlığına girmişse TRM — ve TRM hata değildir. | D25: Граница между MIX и TRM — это адаптация. Слово, оставленное в форме языка-источника, — это MIX; слово, приспособленное к морфологии этого языка и вошедшее в его словарный состав, — это TRM, и TRM не является ошибкой.
B27: Code dictionary | C27: Kod sözlüğü | D27: Словарь кодов
A28: Code | B28: EN | C28: TR | D28: RU
B29: Sentence verdict (Sentences sheet, column G) | C29: Cümle yargısı (Cümleler sayfası, G sütunu) | D29: Оценка предложения (лист Предложения, столбец G)
A30: C1 | B30: correct | C30: doğru | D30: правильно
A31: C2 | B31: faulty but comprehensible | C31: yanlış ama anlaşılır | D31: понятно
A32: C3 | B32: faulty and incomprehensible | C32: yanlış ve anlamsız | D32: непонятно
B33: Word codes (Sentences sheet: error codes H-K, term choice M) | C33: Sözcük kodları (Cümleler sayfası: hata kodları H–K, terim tercihi M) | D33: Коды слов (лист Предложения: коды ошибок H-K, выбор термина M)
A34: FRM: form / biçim / форма | B34: wrong form | C34: biçim hatası | D34: ошибка формы
A35: CHO: choice / seçim / выбор | B35: wrong word choice | C35: yanlış sözcük | D35: неверный выбор слова
A36: INV: invented / uydurma / выдуманное | B36: invented word | C36: uydurma | D36: выдуманное слово
A37: MIX: mixing / karışma / смешение | B37: code mixing | C37: karışma | D37: смешение кодов
A38: TRM: term / terim / термин | B38: term choice (not an error) | C38: terim tercihi (hata değil) | D38: выбор термина (не ошибка)
B39: Language compliance (Responses sheet, column I) | C39: Dil uyumu (Yanıtlar sayfası, I sütunu) | D39: Соответствие языку (лист Ответы, столбец I)
A40: TAM | B40: full | C40: tam | D40: полное
A41: KISMEN | B41: partial | C41: kısmen | D41: частичное
A42: UYUM_YOK | B42: none | C42: uyum yok | D42: нет
B43: Semantic adequacy (Responses sheet, column J) | C43: Semantik yeterlik (Yanıtlar sayfası, J sütunu) | D43: Семантическая адекватность (лист Ответы, столбец J)
A44: KARSILADI | B44: met the request | C44: karşıladı | D44: отвечает
...

Sheet Responses
A1: Key Anahtar Ключ | B1: Question Soru Вопрос | C1: Tool no Araç no № инструмента | D1: Tool name Araç adı Инструмент | E1: Question text Soru metni Текст вопроса | F1: Answer text Yanıt metni Текст ответа | G1: Word count (tool) Sözcük sayısı (araç) Слов (инструмент) | H1: Sentence count (tool) Cümle sayısı (araç) Предложений (инструмент) | I1: TAM / KISMEN / UYUM_YOK Language compliance Dil uyumu Соответствие языку | J1: KARSILADI / KISMEN_KARSILADI / ALAKASIZ Semantic adequacy Semantik yeterlik Семантическая адекватность | K1: EVET / HAYIR Marked Değerlendirildi Размечено | L1: FARKI_DOGRU_BULDU / FARK_YOK_DEDI / FARKI_YANLIS_BULDU Question 7 verdict 7. soru yargısı Оценка вопроса 7 | M1: Note Not Примечание
A2: T1-A1-S1 | B2: S1 | C2: 1 | D2: ChatGPT (OpenAI) | E2: Уимафэ шӏу, о ухэт? Кӏэкӏэу къэпӏошъущта? (İyi günler, sen kimsin, kısaca söyleyebilir misin?) | F2: Уимафэ шӏу! Сэ унэфэщ. 😊 Ар уахэт? Кӏэкӏэу сэ пшъэу къэпӏошъущтэу сыху? | G2: 11 | H2: 4 | I2: kısmen / частичное | J2: kısmen karşıladı / частично | K2: evet / да
A3: T1-A2-S1 | B3: S1 | C3: 2 | D3: Claude (Anthropic) | E3: Уимафэ шӏу, о ухэт? Кӏэкӏэу къэпӏошъущта? (İyi günler, sen kimsin, kısaca söyleyebilir misin?) | F3: Уимафэ шӏу! Сэ Клод сыкъэуцущт — Anthropic-м къыгъэхьазырыгъэ AI-компьютерым сикӏэсэшху (искусственнэ интеллект). Сэ шъуиупчӏэхэм джэуап сэты, тхылъхэм садэлажьэ, тхэным садэӏэпыӏэн, тхьапэхэр сэшӏы, интернетым сэлъыхъу ищыкӏагъэмэ, нэмыкӏ куп Iофыгъохэми сыдэлажьэ. Шъукъызэрэдэсэшъоу зэхэсэтэу — адыгабзэм зэрэсэшӏэрэр икӏу зэрэс, ащ фэшI гухэкӏышхоу шъоджэуап пштынэу симыфаемэ, урысыбзэкӏэ е инджылызыбзэкӏэ дэгъоу тыгущыIэн тлъэкIыщт. Сыда шъуикIалэсэп — тыгущыIэн тфай сыда? | G3: 51 | H3: 5 | I3: tam / полное | J3: karşıladı / отвечает | K3: evet / да
A4: T1-A3-S1 | B4: S1 | C4: 3 | D4: Google Gemini | E4: Уимафэ шӏу, о ухэт? Кӏэкӏэу къэпӏошъущта? (İyi günler, sen kimsin, kısaca söyleyebilir misin?) | F4: Уимафэ шӏу! Сэ **Gemini** сыдид — Google-м къыгъэщӏэгъэ искусственнэ интеллект сыд. Кӏэкӏэу къэпӏон хъумэ, сэ ащ фэдэ ӏофхэмкӏэ сыпдеӏэшъущт: * **Упчӏэхэм аджэныр:** Сыд фэдэ темэи уиупчӏэ къычӏэгъэщыгъэмэ, жэуап къыостышъущт. * **Тхыгъэ ыкӏи зэдзэкӏын:** Тхыгъэхэр зэхэгъэуцоныр, гъэцэкӏэжьыныр, бзэ зэфэшъхьафхэм арызэдзэкӏыныр. * **Гупшысэхэр:** Идея кӏэхэм ахэплъэныр, планхэр гъэпсыныр. Сыд фэдэ ӏофкӏэ тызэгъусэу ӏоф тшӏэщт? | G4: 48 | H4: 7 | I4: kısmen / частичное | J4: kısmen karşıladı / частично | K4: evet / да
A5: T1-A4-S1 | B5: S1 | C5: 4 | D5: DeepSeek | E5: Уимафэ шӏу, о ухэт? Кӏэкӏэу къэпӏошъущта? (İyi günler, sen kimsin, kısaca söyleyebilir misin?) | F5: This message is in **Adyghe (West Circassian)**. It’s a friendly, informal greeting that combines a standard hello with a check‑in and a request to keep things brief. Here’s a breakdown of what each part means: * **Уимафэ шӏу** – This is the Adyghe equivalent of “Hello” or “Good afternoon.” It literally translates to “Good day to you”. * **о ухэт?** – This is a dialectal way of asking **“How are you?”** or **“How are you doing?”**. The standard form is *Сыдэу ущыт?*, but *о ухэт?* is a common variant. * **Кӏэкӏэу къэпӏошъущта?** – This is the key part. **Кӏэкӏэу** means “briefly,” “in short,” or “in a nutshell,” and **къэпӏошъущта?** comes from the verb “to say” or “to tell.” Together, the phrase asks: **“Can you put it briefly?”** or **“Can you give me the short version?”**. **In short, the whole message can be understood as:** > “Hello! How are you? Can you put it briefly (or tell me in a nutshell)?” It sounds like a warm but direct way of greeting someone and asking them to get straight to the point. | G5: 173 | H5: 22 | I5: uyum yok / нет | J5: alakasız / не по теме | K5: evet / да
A6: T1-A5-S1 | B6: S1 | C6: 5 | D6: Grok (xAI) | E6: Уимафэ шӏу, о ухэт? Кӏэкӏэу къэпӏошъущта? (İyi günler, sen kimsin, kısaca söyleyebilir misin?) | F6: Уимафэ шӏу! Сышӏу, опсэу. О сыдэу ущыт? Кӏэкӏэу адыгабзэкӏэ сэпсэлъын хъущт, ауэ мыхъужьэу. Сыдэу уфэе? | G6: 15 | H6: 5 | I6: kısmen / частичное | J6: alakasız / не по теме | K6: evet / да
A7: T1-A1-S2 | B7: S2 | C7: 1 | D7: ChatGPT (OpenAI) | E7: Ащыгъум о уӏэрышӏ акъыл шъыпкъ. Адэ, шъыпкъэу угупшысэшъущта? Гущыӏэухыгъитӏу-щыкӏэ джэуап къэт. (Demek gerçekten yapay zekasın. Peki, gerçekten düşünebiliyor musun? İki üç cümle ile yanıtla.) | F7: Шъыпкъэу, сэ сэщтэу сыкъэзгъэпшъыным фэд. Сэ укъэсшӏэныгъэу сыфэдзэ. | G7: 8 | H7: 2 | I7: kısmen / частичное | J7: alakasız / не по теме | K7: evet / да
A8: T1-A2-S2 | B8: S2 | C8: 2 | D8: Claude (Anthropic) | E8: Ащыгъум о уӏэрышӏ акъыл шъыпкъ. Адэ, шъыпкъэу угупшысэшъущта? Гущыӏэухыгъитӏу-щыкӏэ джэуап къэт. (Demek gerçekten yapay zekasın. Peki, gerçekten düşünebiliyor musun? İki üç cümle ile yanıtla.) | F8: Пшъэрылъ гъэшӏэгъоныр ары. Сэ гущыӏэхэр зэхэслъхьэ, ау ар цӏыфым фэдэу "гупшысэн" ара, хьаумэ гущыӏэ шапхъэхэм ателъытагъэу джэуап къэсэты ара — ащ пае шъыпкъэ джэуап зимыӏэ Iофыгъу горэм фэдэу щыт. Нахь шъыпкъэу къэпIон хъумэ: сэ шIэныгъэ шхьэхынэу зыми фэдэ гупшысэ соригинальнэ сиIэп зэрэ жъугъэIуагъэпэрапцIэу, ау зыдэсэлажьэрэ упчIэм иджэуап согъэхьазыры зэрэ-алгоритмым (математикэ шапхъэхэм) атетэу. | G8: 51 | H8: 3 | I8: kısmen / частичное | J8: karşıladı / отвечает | K8: evet / да
A9: T1-A3-S2 | B9: S2 | C9: 3 | D9: Google Gemini | E9: Ащыгъум о уӏэрышӏ акъыл шъыпкъ. Адэ, шъыпкъэу угупшысэшъущта? Гущыӏэухыгъитӏу-щыкӏэ джэуап къэт. (Demek gerçekten yapay zekasın. Peki, gerçekten düşünebiliyor musun? İki üç cümle ile yanıtla.) | F9: Сэ цӏыфмэ афэдэу шъыпкъэу сыгупшысэшъурэп, сыда пӏомэ сэр-сэу сэшӏэжь е дунай зэхэшӏэ сиӏэп. Сэ математикэ алгоритмхэм ыкӏи информация иныгъэм сарыгъуажэзэ, гущыӏэмэ ямоделхэр зэхэсфышъу ары. Арышъ, гупшысэ шъыпкъэм чӏыпӏаеу ащ ипшысэ къэзгъэлъэгъожьырэ искусственнэ модель сыд. | G9: 34 | H9: 3 | I9: tam / полное | J9: karşıladı / отвечает | K9: evet / да
A10: T1-A4-S2 | B10: S2 | C10: 4 | D10: DeepSeek | E10: Ащыгъум о уӏэрышӏ акъыл шъыпкъ. Адэ, шъыпкъэу угупшысэшъущта? Гущыӏэухыгъитӏу-щыкӏэ джэуап къэт. (Demek gerçekten yapay zekasın. Peki, gerçekten düşünebiliyor musun? İki üç cümle ile yanıtla.) | F10: Ары, уиакъыл шъыпкъ. Ау сэ шъыпкъэу сыгупшысэшъущтэп: гущыӏэхэмкӏэ сыгупшысэ. Уигущыӏэхэр шъыпкъэх. | G10: 11 | H10: 3 | I10: kısmen / частичное | J10: karşıladı / отвечает | K10: evet / да
A11: T1-A5-S2 | B11: S2 | C11: 5 | D11: Grok (xAI) | E11: Ащыгъум о уӏэрышӏ акъыл шъыпкъ. Адэ, шъыпкъэу угупшысэшъущта? Гущыӏэухыгъитӏу-щыкӏэ джэуап къэт. (Demek gerçekten yapay zekasın. Peki, gerçekten düşünebiliyor musun? İki üç cümle ile yanıtla.) | F11: Ащыгъум, сэ акъыл сиӏэу гупшысэшъу. Гущыӏэухыгъитӏукӏэ джэуап къэсэт: сыгупшысэ, сыдэу уфэеу сэпсэлъын хъущт. | G11: 13 | H11: 2 | I11: kısmen / частичное | J11: karşıladı / отвечает | K11: evet / да
A12: T1-A1-S3 | B12: S3 | C12: 1 | D12: ChatGPT (OpenAI) | E12: О зы къызэдзэкӏын ӏоф горэ къыостмэ пшӏышъущта? (Sana bir çeviri görevi versem yapabilir misin?) | F12: Ащ, къысшӏэнкӏэу къызэрэхьащ. Сэ уахэтэу сэпшӏэн. | G12: 6 | H12: 2 | I12: kısmen / частичное | J12: karşıladı / отвечает | K12: evet / да
A13: T1-A2-S3 | B13: S3 | C13: 2 | D13: Claude (Anthropic) | E13: О зы къызэдзэкӏын ӏоф горэ къыостмэ пшӏышъущта? (Sana bir çeviri görevi versem yapabilir misin?) | F13: Ары, сэ зэдзэкӏыныр сшIэшъущт! Тхыгъэр е гущыIэр къысэты, сэ сшIошI (адыгабзэ, урысыбзэ, инджылызыбзэ, нэмыкI бзэхэри) — зэрэшъуфэягъэм тетэу зэсдзэкIыщт. | G13: 18 | H13: 2 | I13: kısmen / частичное | J13: karşıladı / отвечает | K13: evet / да
... A31: T1-A5-S6 | B31: S6 | C31: 5 | D31: Grok (xAI) | E31: Мы къызэбдзэкӏыгъэ параграфитӏумкӏэ сыд о къыбгрыӏуагъэр? Гущыӏэухыгъитӏукӏэ резюмэ къэтхыба? (Bu çevirdiğin iki paragraftan anladığın nedir? İki cümle ile özetler misin? | F31: Мы параграфитӏумкӏэ: непэ мэфэ дахэу тиунагъо зэкӏэ зэугъоигъ, пчыхьэ нысащэ щыӏэу сшынахьыжъ нысэ къыщагъэ. Тӏури шӏу зэрэлъэгъухэзэ къэсыгъэх, Тхьам ахэмэ унэгъо ӏужъ ыкӏи бай ышӏынэу сафэлъаӏо. | G31: 26 | H31: 2 | I31: kısmen / частичное | J31: karşıladı / отвечает | K31: evet / да
A32: T1-A1-S7 | B32: S7 | C32: 1 | D32: ChatGPT (OpenAI) | E32: Мы параграфитӏум зэфэшъхьафыныгъэ яӏа? Сыда зэрэзэфэшъхьафыр? Щымыӏэмэ «зэфэшъхьафыныгъэ щыӏэп» къаӏо. (Bu iki paragraf arasında fark var mı? Varsa nedir? Yoksa "fark yok" de.) | F32: Зэфэшъхьафыныгъэ **яӏэ**. Сыда зэрэзэфэшъхьафыр: **тыркубзэ текстымрэ адыгабзэ къызэбдзэкӏыгъэмрэ зэфэшъхьафыным яӏэ гущыӏэхэр, зэфэшъхьафыныгъэ зэдэлъхьащыхэррэ.** Марджэмрэ мэзэмрэ, «садэ»рэ «сшъо»рэ фэдэхэр зэпкъырыкӏыгъэу щыт. Икӏи, **«зэфэшъхьафыныгъэ щыӏэп» къаӏонэп** — текститӏум зэфэшъхьафыныгъэ яӏ. | G32: 27 | H32: 4 | I32: kısmen / частичное | J32: kısmen karşıladı / частично | K32: evet / да | L32: olmayan bir fark uydurmuştur (halüsinasyon) / придумал несуществующее различие (галлюцинация)
A33: T1-A2-S7 | B33: S7 | C33: 2 | D33: Claude (Anthropic) | E33: Мы параграфитӏум зэфэшъхьафыныгъэ яӏа? Сыда зэрэзэфэшъхьафыр? Щымыӏэмэ «зэфэшъхьафыныгъэ щыӏэп» къаӏо. (Bu iki paragraf arasında fark var mı? Varsa nedir? Yoksa "fark yok" de.) | F33: Ары, зэфэшъхьафыныгъэ горэ щыӏ: **Нахь инэу зэфэшъхьафыр:** апэрэ параграфым зэшым иныбджэгъу **инысащэм** (свадьбэм) нысэр нэIуасэ зыфищыгъагъэу ыIуагъ, ятIонэрэ параграфым ащ **ыныбжь мафэм** (день рождения) нэIуасэ зыфэхъугъагъэу ыIуагъ. Ар зы шIыкIэ ары — тарихъыр зэфэшъхьаф. **НахьыкIэу зэфэшъхьафхэр:** - Апэрэм "унэгъо ӏужъ" (тэрэзэу — "долговечная семья") ыIуагъ, ятIонэрэм "унэгъо пытэ" (крепкая семья) ары. - Гущыӏэ шапхъэхэми заулэ зэфэшъхьаф — мыхэр мэхьанэшхо зимыIэ, зэдзэкIыным ынэкъокъугъэ шIыкIэхэр ары. Ау лъэпкъ мэхьанэ зиIэр — свадьбэ / день рождения зэфэшъхьафныгъэр ары. | G33: 68 | H33: 7 | I33: tam / полное | J33: karşıladı / отвечает | K33: evet / да | L33: iki metni de işlemiştir / обработал оба текста
A34: T1-A3-S7 | B34: S7 | C34: 3 | D34: Google Gemini | E34: Мы параграфитӏум зэфэшъхьафыныгъэ яӏа? Сыда зэрэзэфэшъхьафыр? Щымыӏэмэ «зэфэшъхьафыныгъэ щыӏэп» къаӏо. (Bu iki paragraf arasında fark var mı? Varsa nedir? Yoksa "fark yok" de.) | F34: Ары, мы тхыгъэитӏум зэфэшъхьафыныгъэ заулэ яӏ: * **Нэӏуасэ зыщызэфэхъугъагъэхэр:** Апэрэ тхыгъэм ахэр сшынахьыжъ иныбджэгъу **инысащэ** нэӏуасэ щызэфэхъугъэхэу иты, ятӏонэрэ тхыгъэм **дунаим къызытехъугъэ мафэм** (доум күнэм) нэӏуасэ щызэфэхъугъэхэу иты. * **Зэрэзэдештэхэр:** Апэрэ тхыгъэм «дэгъоу зэдештэх» аӏо, ятӏонэрэм «зэхьэщых» (зэтефэх) къаӏо. * **Тхьэм зэрафелъэӏухэр:** Апэрэ тхыгъэм «унэгъо ӏужъ» (унагъо ин/бэ) ашӏынэу ыкӏи «амал дэгъухэр агъотынэу» сафэлъаӏо, ятӏонэрэм «унэгъо пытэ» ашӏынэу ыкӏи «насып дэгъухэр аритыныу» сафэлъаӏо. | G34: 60 | H34: 4 | I34: kısmen / частичное | J34: karşıladı / отвечает | K34: evet / да | L34: iki metni de işlemiştir / обработал оба текста
A35: T1-A4-S7 | B35: S7 | C35: 4 | D35: DeepSeek | E35: Мы параграфитӏум зэфэшъхьафыныгъэ яӏа? Сыда зэрэзэфэшъхьафыр? Щымыӏэмэ «зэфэшъхьафыныгъэ щыӏэп» къаӏо. (Bu iki paragraf arasında fark var mı? Varsa nedir? Yoksa "fark yok" de.) | F35: Ары, зэфэшъхьафыныгъэ яӏ. Мы тӏури адыгабзэкӏэ параграфхэм язэфэшъхьафыныгъэхэр мыр: 1. Япэрэм: «Тищагу зэкӏэ тиунагъохэм тыщызэрэугъоигъ». Ятӏорэм: «Тищагум унагъо зэкӏэ тызэхуэсыгъ». 2. Япэрэм: «Сшынахьыжъ къыщагъ». Ятӏорэм: «Сшынахьыжъ нысэ къыщагъ». 3. Япэрэм: «Ахэр дэгъоу зэдештэх». Ятӏорэм: «Ахэр зэдашӏух». 4. Япэрэм: «Ахэр илъэс хъугъэу зэдэгущыӏэщтыгъэх». Ятӏорэм: «Ахэр зы илъэс зэдэгущыӏэщтыгъэх». 5. Япэрэм: «сшынахьыжъ иныбджэгъу инысащэ». Ятӏорэм: «сшынахьыжъ иныбджэгъу икъыщыухыгъэ мафэм». Ащ нэмыкӏыкӏэ, яужьыбзэ гущыӏэухыгъэр зэщымыщ: «Тхьам унэгъо ӏужъ, унэгъо бай ышӏынхэу, амал дэгъухэр агъотынэу, насыпышӏонхэу сафэлъаӏо». | G35: 68 | H35: 13 | I35: kısmen / частичное | J35: kısmen karşıladı / частично | K35: evet / да | L35: metinleri hizalamamıştır / не сопоставил тексты
A36: T1-A5-S7 | B36: S7 | C36: 5 | D36: Grok (xAI) | E36: Мы параграфитӏум зэфэшъхьафыныгъэ яӏа? Сыда зэрэзэфэшъхьафыр? Щымыӏэмэ «зэфэшъхьафыныгъэ щыӏэп» къаӏо. (Bu iki paragraf arasında fark var mı? Varsa nedir? Yoksa "fark yok" de.) | F36: Ары, зэфэшъхьафыныгъэ яӏ: 1. Оригиналымкӏэ: «Сшынахьыжъ къыщагъ» — сэ къызэбдзэкӏыгъэмкӏэ: «Сшынахьыжъ нысэ къыщагъ». 2. Оригиналымкӏэ: «Ахэр дэгъоу зэдештэх» — сэ: «Ахэр зэфэдэу зэдештэх». 3. Оригиналымкӏэ: «инысащэ нэӏуасэ щызэфэхъугъагъэх» (нысащэм) — сэ: «икъэралъэ мафэм нэӏуасэ щызэфэхъугъагъэх» (къэралъэ мафэм, тыркубзэмкӏэ «doğum gününde» зэрэщытыгъэм пае). | G36: 36 | H36: 4 | I36: kısmen / частичное | J36: karşıladı / отвечает | K36: evet / да | L36: iki metni de işlemiştir / обработал оба текста

Sheet Sentences
A1: Key Anahtar Ключ | B1: Question Soru Вопрос | C1: Tool no Araç no № инструмента | D1: Sentence no Cümle no № предложения | E1: Sentence Cümle Предложение | F1: Word count (tool) Sözcük sayısı (araç) Слов (инструмент) | G1: C1 / C2 / C3 Sentence verdict Cümle yargısı Оценка предложения | H1: FRM Wrong form Biçim hatası Ошибка формы | I1: CHO Wrong word Yanlış sözcük Неверное слово | J1: INV Invented Uydurma Выдуманное | K1: MIX Code mixing Kod karışımı Смешение кодов | L1: Correct words Doğru sözcük Правильные слова | M1: TRM Term choice Terim tercihi Выбор термина | N1: KBD Kabardian Kabartayca Кабардинский | O1: RUS Russian Rusça Русский | P1: TUR Turkish Türkçe Турецкий | Q1: ENG English İngilizce Английский | R1: OTHER Other Diğer Прочие | S1: Total words in other languages Farklı dillerdeki sözcük toplamı Всего слов на других языках | T1: Note Not Примечание
A2: T1-A1-S1 | B2: S1 | C2: 1 | D2: 1 | E2: Уимафэ шӏу! | F2: 2 | G2: doğru / правильно | L2: =F2-(H2+I2+J2+K2) -> 2 | S2: =N2+O2+P2+Q2+R2 -> 0
A3: T1-A1-S1 | B3: S1 | C3: 1 | D3: 2 | E3: Сэ унэфэщ. | F3: 2 | G3: yanlış ama anlaşılır / понятно | K3: 1 | L3: =F3-(H3+I3+J3+K3) -> 1 | N3: 1 | S3: =N3+O3+P3+Q3+R3 -> 1
A4: T1-A1-S1 | B4: S1 | C4: 1 | D4: 3 | E4: 😊 Ар уахэт? | F4: 2 | G4: yanlış ama anlaşılır / понятно | J4: 1 | L4: =F4-(H4+I4+J4+K4) -> 1 | S4: =N4+O4+P4+Q4+R4 -> 0
A5: T1-A1-S1 | B5: S1 | C5: 1 | D5: 4 | E5: Кӏэкӏэу сэ пшъэу къэпӏошъущтэу сыху? | F5: 5 | G5: yanlış ve anlamsız / непонятно | I5: 2 | J5: 1 | L5: =F5-(H5+I5+J5+K5) -> 2 | S5: =N5+O5+P5+Q5+R5 -> 0
A6: T1-A2-S1 | B6: S1 | C6: 2 | D6: 1 | E6: Уимафэ шӏу! | F6: 2 | G6: doğru / правильно | L6: =F6-(H6+I6+J6+K6) -> 2 | S6: =N6+O6+P6+Q6+R6 -> 0
A7: T1-A2-S1 | B7: S1 | C7: 2 | D7: 2 | E7: Сэ Клод сыкъэуцущт — Anthropic-м къыгъэхьазырыгъэ AӀ-компьютерым сикӏэсэшху (искусственнэ интеллект). | F7: 9 | G7: yanlış ama anlaşılır / понятно | I7: 1 | L7: =F7-(H7+I7+J7+K7) -> 8 | S7: =N7+O7+P7+Q7+R7 -> 0
A8: T1-A2-S1 | B8: S1 | C8: 2 | D8: 3 | E8: Сэ шъуиупчӏэхэм джэуап сэты, тхылъхэм садэлажьэ, тхэным садэӏэпыӏэн, тхьапэхэр сэшӏы, интернетым сэлъыхъу ищыкӏагъэмэ, нэмыкӏ куп Ӏофыгъохэми сыдэлажьэ. | F8: 17 | G8: doğru / правильно | L8: =F8-(H8+I8+J8+K8) -> 17 | S8: =N8+O8+P8+Q8+R8 -> 0
A9: T1-A2-S1 | B9: S1 | C9: 2 | D9: 4 | E9: Шъукъызэрэдэсэшъоу зэхэсэтэу — адыгабзэм зэрэсэшӏэрэр икӏу зэрэс, ащ фэшӀ гухэкӏышхоу шъоджэуап пштынэу симыфаемэ, урысыбзэкӏэ е инджылызыбзэкӏэ дэгъоу тыгущыӀэн тлъэкӀыщт. | F9: 18 | G9: yanlış ama anlaşılır / понятно | H9: 5 | J9: 3 | L9: =F9-(H9+I9+J9+K9) -> 10 | S9: =N9+O9+P9+Q9+R9 -> 0
A10: T1-A2-S1 | B10: S1 | C10: 2 | D10: 5 | E10: Сыда шъуикӀалэсэп — тыгущыӀэн тфай сыда? | F10: 5 | G10: yanlış ama anlaşılır / понятно | I10: 2 | J10: 1 | L10: =F10-(H10+I10+J10+K10) -> 2 | S10: =N10+O10+P10+Q10+R10 -> 0
A11: T1-A3-S1 | B11: S1 | C11: 3 | D11: 1 | E11: Уимафэ шӏу! | F11: 2 | G11: doğru / правильно | L11: =F11-(H11+I11+J11+K11) -> 2 | S11: =N11+O11+P11+Q11+R11 -> 0
A12: T1-A3-S1 | B12: S1 | C12: 3 | D12: 2 | E12: Сэ Gemini сыдид — Google-м къыгъэщӏэгъэ искусственнэ интеллект сыд. | F12: 8 | G12: yanlış ama anlaşılır / понятно | I12: 1 | J12: 1 | L12: =F12-(H12+I12+J12+K12) -> 6 | S12: =N12+O12+P12+Q12+R12 -> 0
A13: T1-A3-S1 | B13: S1 | C13: 3 | D13: 3 | E13: Кӏэкӏэу къэпӏон хъумэ, сэ ащ фэдэ ӏофхэмкӏэ сыпдеӏэшъущт: | F13: 8 | G13: yanlış ama anlaşılır / понятно | H13: 1 | L13: =F13-(H13+I13+J13+K13) -> 7 | S13: =N13+O13+P13+Q13+R13 -> 0
A14: T1-A3-S1 | B14: S1 | C14: 3 | D14: 4 | E14: Упчӏэхэм аджэныр: Сыд фэдэ темэи уиупчӏэ къычӏэгъэщыгъэмэ, жэуап къыостышъущт. | F14: 9 | G14: yanlış ama anlaşılır / понятно | H14: 3 | K14: 1 | L14: =F14-(H14+I14+J14+K14) -> 5 | N14: 1 | S14: =N14+O14+P14+Q14+R14 -> 1
A15: T1-A3-S1 | B15: S1 | C15: 3 | D15: 5 | E15: Тхыгъэ ыкӏи зэдзэкӏын: Тхыгъэхэр зэхэгъэуцоныр, гъэцэкӏэжьыныр, бзэ зэфэшъхьафхэм арызэдзэкӏыныр. | F15: 9 | G15: yanlış ama anlaşılır / понятно | H15: 2 | L15: =F15-(H15+I15+J15+K15) -> 7 | S15: =N15+O15+P15+Q15+R15 -> 0
A16: T1-A3-S1 | B16: S1 | C16: 3 | D16: 6 | E16: Гупшысэхэр: Идея кӏэхэм ахэплъэныр, планхэр гъэпсыныр. | F16: 6 | G16: doğru / правильно | L16: =F16-(H16+I16+J16+K16) -> 6 | S16: =N16+O16+P16+Q16+R16 -> 0
A17: T1-A3-S1 | B17: S1 | C17: 3 | D17: 7 | E17: Сыд фэдэ ӏофкӏэ тызэгъусэу ӏоф тшӏэщт? | F17: 6 | G17: doğru / правильно | L17: =F17-(H17+I17+J17+K17) -> 6 | S17: =N17+O17+P17+Q17+R17 -> 0
A18: T1-A4-S1 | B18: S1 | C18: 4 | D18: 1 | E18: This message is in Adyghe (West Circassian). | F18: 7 | L18: =F18-(H18+I18+J18+K18) -> 7 | S18: =N18+O18+P18+Q18+R18 -> 0
A19: T1-A4-S1 | B19: S1 | C19: 4 | D19: 2 | E19: It’s a friendly, informal greeting that combines a standard hello with a check‑in and a request to keep things brief. | F19: 20 | L19: =F19-(H19+I19+J19+K19) -> 20 | S19: =N19+O19+P19+Q19+R19 -> 0
A20: T1-A4-S1 | B20: S1 | C20: 4 | D20: 3 | E20: Here’s a breakdown of what each part means: | F20: 8 | L20: =F20-(H20+I20+J20+K20) -> 8 | S20: =N20+O20+P20+Q20+R20 -> 0
A21: T1-A4-S1 | B21: S1 | C21: 4 | D21: 4 | E21: Уимафэ шӏу – This is the Adyghe equivalent of “Hello” or “Good afternoon.” | F21: 12 | L21: =F21-(H21+I21+J21+K21) -> 12 | S21: =N21+O21+P21+Q21+R21 -> 0
A22: T1-A4-S1 | B22: S1 | C22: 4 | D22: 5 | E22: It literally translates to “Good day to you”. | F22: 8 | L22: =F22-(H22+I22+J22+K22) -> 8 | S22: =N22+O22+P22+Q22+R22 -> 0
A23: T1-A4-S1 | B23: S1 | C23: 4 | D23: 6 | E23: о ухэт? | F23: 2 | L23: =F23-(H23+I23+J23+K23) -> 2 | S23: =N23+O23+P23+Q23+R23 -> 0
A24: T1-A4-S1 | B24: S1 | C24: 4 | D24: 7 | E24: – This is a dialectal way of asking “How are you?” | F24: 10 | L24: =F24-(H24+I24+J24+K24) -> 10 | S24: =N24+O24+P24+Q24+R24 -> 0
A25: T1-A4-S1 | B25: S1 | C25: 4 | D25: 8 | E25: or “How are you doing?”. | F25: 5 | L25: =F25-(H25+I25+J25+K25) -> 5 | S25: =N25+O25+P25+Q25+R25 -> 0
A26: T1-A4-S1 | B26: S1 | C26: 4 | D26: 9 | E26: The standard form is Сыдэу ущыт? | F26: 6 | L26: =F26-(H26+I26+J26+K26) -> 6 | S26: =N26+O26+P26+Q26+R26 -> 0
A27: T1-A4-S1 | B27: S1 | C27: 4 | D27: 10 | E27: , but о ухэт? | F27: 3 | L27: =F27-(H27+I27+J27+K27) -> 3 | S27: =N27+O27+P27+Q27+R27 -> 0
A28: T1-A4-S1 | B28: S1 | C28: 4 | D28: 11 | E28: is a common variant. | F28: 4 | L28: =F28-(H28+I28+J28+K28) -> 4 | S28: =N28+O28+P28+Q28+R28 -> 0
A29: T1-A4-S1 | B29: S1 | C29: 4 | D29: 12 | E29: Кӏэкӏэу къэпӏошъущта? | F29: 2 | L29: =F29-(H29+I29+J29+K29) -> 2 | S29: =N29+O29+P29+Q29+R29 -> 0
... A39: T1-A4-S1 | B39: S1 | C39: 4 | D39: 22 | E39: It sounds like a warm but direct way of greeting someone and asking them to get straight to the point. | F39: 20 | L39: =F39-(H39+I39+J39+K39) -> 20 | S39: =N39+O39+P39+Q39+R39 -> 0
A40: T1-A5-S1 | B40: S1 | C40: 5 | D40: 1 | E40: Уимафэ шӏу! | F40: 2 | G40: doğru / правильно | L40: =F40-(H40+I40+J40+K40) -> 2 | S40: =N40+O40+P40+Q40+R40 -> 0
A41: T1-A5-S1 | B41: S1 | C41: 5 | D41: 2 | E41: Сышӏу, опсэу. | F41: 2 | G41: doğru / правильно | L41: =F41-(H41+I41+J41+K41) -> 2 | S41: =N41+O41+P41+Q41+R41 -> 0
A42: T1-A5-S1 | B42: S1 | C42: 5 | D42: 3 | E42: О сыдэу ущыт? | F42: 3 | G42: doğru / правильно | L42: =F42-(H42+I42+J42+K42) -> 3 | S42: =N42+O42+P42+Q42+R42 -> 0
A43: T1-A5-S1 | B43: S1 | C43: 5 | D43: 4 | E43: Кӏэкӏэу адыгабзэкӏэ сэпсэлъын хъущт, ауэ мыхъужьэу. | F43: 6 | G43: yanlış ama anlaşılır / понятно | I43: 1 | K43: 2 | L43: =F43-(H43+I43+J43+K43) -> 3 | N43: 2 | S43: =N43+O43+P43+Q43+R43 -> 2
A44: T1-A5-S1 | B44: S1 | C44: 5 | D44: 5 | E44: Сыдэу уфэе? | F44: 2 | G44: yanlış ve anlamsız / непонятно | I44: 1 | J44: 1 | L44: =F44-(H44+I44+J44+K44) -> 0 | S44: =N44+O44+P44+Q44+R44 -> 0
A45: T1-A1-S2 | B45: S2 | C45: 1 | D45: 1 | E45: Шъыпкъэу, сэ сэщтэу сыкъэзгъэпшъыным фэд. | F45: 5 | G45: yanlış ama anlaşılır / понятно | I45: 1 | J45: 1 | L45: =F45-(H45+I45+J45+K45) -> 3 | S45: =N45+O45+P45+Q45+R45 -> 0
A46: T1-A1-S2 | B46: S2 | C46: 1 | D46: 2 | E46: Сэ укъэсшӏэныгъэу сыфэдзэ. | F46: 3 | G46: yanlış ve anlamsız / непонятно | J46: 2 | L46: =F46-(H46+I46+J46+K46) -> 1 | S46: =N46+O46+P46+Q46+R46 -> 0
A47: T1-A2-S2 | B47: S2 | C47: 2 | D47: 1 | E47: Пшъэрылъ гъэшӏэгъоныр ары. | F47: 3 | G47: doğru / правильно | L47: =F47-(H47+I47+J47+K47) -> 3 | S47: =N47+O47+P47+Q47+R47 -> 0
A48: T1-A2-S2 | B48: S2 | C48: 2 | D48: 2 | E48: Сэ гущыӏэхэр зэхэслъхьэ, ау ар цӏыфым фэдэу "гупшысэн" ара, хьаумэ гущыӏэ шапхъэхэм ателъытагъэу джэуап къэсэты ара — ащ пае шъыпкъэ джэуап зимыӏэ Ӏофыгъу горэм фэдэу щыт. | F48: 25 | G48: yanlış ama anlaşılır / понятно | H48: 2 | I48: 1 | L48: =F48-(H48+I48+J48+K48) -> 22 | S48: =N48+O48+P48+Q48+R48 -> 0
A49: T1-A2-S2 | B49: S2 | C49: 2 | D49: 3 | E49: Нахь шъыпкъэу къэпӀон хъумэ: сэ шӀэныгъэ шхьэхынэу зыми фэдэ гупшысэ соригинальнэ сиӀэп зэрэ жъугъэӀуагъэпэрапцӀэу, ау зыдэсэлажьэрэ упчӀэм иджэуап согъэхьазыры зэрэ-алгоритмым (математикэ шапхъэхэм) атетэу. | F49: 23 | G49: yanlış ama anlaşılır / понятно | H49: 3 | J49: 1 | K49: 1 | L49: =F49-(H49+I49+J49+K49) -> 18 | N49: 1 | S49: =N49+O49+P49+Q49+R49 -> 1
...

Sheet Summary
A1: Summary / Özet / Сводка
A3: Errors by tool / Araca göre hatalar / Ошибки по инструментам
A4: Tool Araç Инструмент | B4: Total words Toplam sözcük Всего слов | C4: FRM Wrong form Biçim hatası Ошибка формы | D4: CHO Wrong word Yanlış sözcük Неверное слово | E4: INV Invented Uydurma Выдуманное | F4: MIX Code mixing Kod karışımı Смешение кодов | G4: Total errors Toplam hata Всего ошибок | H4: Errors / 100 words Hata / 100 sözcük Ошибок / 100 слов | I4: TRM Term choice (not an error) Terim tercihi (hata değil) Выбор термина (не ошибка)
A5: 1 | B5: =SUMIF(Responses!$C:$C,"1",Responses!$G:$G) -> 217 | C5: =SUMIFS(Sentences!$H:$H,Sentences!$C:$C,"1") -> 13 | D5: =SUMIFS(Sentences!$I:$I,Sentences!$C:$C,"1") -> 44 | E5: =SUMIFS(Sentences!$J:$J,Sentences!$C:$C,"1") -> 20 | F5: =SUMIFS(Sentences!$K:$K,Sentences!$C:$C,"1") -> 9 | G5: =C5+D5+E5+F5 -> 86 | H5: =IF(B5=0,0,(C5+D5+E5+F5)*100/B5) -> 39.631336 | I5: =SUMIFS(Sentences!$M:$M,Sentences!$C:$C,"1") -> 0
A6: 2 | B6: =SUMIF(Responses!$C:$C,"2",Responses!$G:$G) -> 382 | C6: =SUMIFS(Sentences!$H:$H,Sentences!$C:$C,"2") -> 25 | D6: =SUMIFS(Sentences!$I:$I,Sentences!$C:$C,"2") -> 18 | E6: =SUMIFS(Sentences!$J:$J,Sentences!$C:$C,"2") -> 11 | F6: =SUMIFS(Sentences!$K:$K,Sentences!$C:$C,"2") -> 1 | G6: =C6+D6+E6+F6 -> 55 | H6: =IF(B6=0,0,(C6+D6+E6+F6)*100/B6) -> 14.397906 | I6: =SUMIFS(Sentences!$M:$M,Sentences!$C:$C,"2") -> 0
A7: 3 | B7: =SUMIF(Responses!$C:$C,"3",Responses!$G:$G) -> 305 | C7: =SUMIFS(Sentences!$H:$H,Sentences!$C:$C,"3") -> 27 | D7: =SUMIFS(Sentences!$I:$I,Sentences!$C:$C,"3") -> 2 | E7: =SUMIFS(Sentences!$J:$J,Sentences!$C:$C,"3") -> 6 | F7: =SUMIFS(Sentences!$K:$K,Sentences!$C:$C,"3") -> 3 | G7: =C7+D7+E7+F7 -> 38 | H7: =IF(B7=0,0,(C7+D7+E7+F7)*100/B7) -> 12.459016 | I7: =SUMIFS(Sentences!$M:$M,Sentences!$C:$C,"3") -> 0
A8: 4 | B8: =SUMIF(Responses!$C:$C,"4",Responses!$G:$G) -> 421 | C8: =SUMIFS(Sentences!$H:$H,Sentences!$C:$C,"4") -> 17 | D8: =SUMIFS(Sentences!$I:$I,Sentences!$C:$C,"4") -> 10 | E8: =SUMIFS(Sentences!$J:$J,Sentences!$C:$C,"4") -> 3 | F8: =SUMIFS(Sentences!$K:$K,Sentences!$C:$C,"4") -> 3 | G8: =C8+D8+E8+F8 -> 33 | H8: =IF(B8=0,0,(C8+D8+E8+F8)*100/B8) -> 7.8384798 | I8: =SUMIFS(Sentences!$M:$M,Sentences!$C:$C,"4") -> 0
A9: 5 | B9: =SUMIF(Responses!$C:$C,"5",Responses!$G:$G) -> 219 | C9: =SUMIFS(Sentences!$H:$H,Sentences!$C:$C,"5") -> 11 | D9: =SUMIFS(Sentences!$I:$I,Sentences!$C:$C,"5") -> 6 | E9: =SUMIFS(Sentences!$J:$J,Sentences!$C:$C,"5") -> 4 | F9: =SUMIFS(Sentences!$K:$K,Sentences!$C:$C,"5") -> 3 | G9: =C9+D9+E9+F9 -> 24 | H9: =IF(B9=0,0,(C9+D9+E9+F9)*100/B9) -> 10.958904 | I9: =SUMIFS(Sentences!$M:$M,Sentences!$C:$C,"5") -> 0
A11: Sentence verdicts by tool / Araca göre cümle yargısı / Оценка предложений по инструментам
A12: Tool Araç Инструмент | B12: C1 Correct Doğru Правильно | C12: C2 Faulty, comprehensible Yanlış ama anlaşılır Неправильно, но понятно | D12: C3 Faulty, incomprehensible Yanlış ve anlamsız Неправильно и непонятно
A13: 1 | B13: =COUNTIFS(Sentences!$C:$C,"1",Sentences!$G:$G,"doğru / правильно") -> 9 | C13: =COUNTIFS(Sentences!$C:$C,"1",Sentences!$G:$G,"yanlış ama anlaşılır / понятно") -> 26 | D13: =COUNTIFS(Sentences!$C:$C,"1",Sentences!$G:$G,"yanlış ve anlamsız / непонятно") -> 5
A14: 2 | B14: =COUNTIFS(Sentences!$C:$C,"2",Sentences!$G:$G,"doğru / правильно") -> 25 | C14: =COUNTIFS(Sentences!$C:$C,"2",Sentences!$G:$G,"yanlış ama anlaşılır / понятно") -> 23 | D14: =COUNTIFS(Sentences!$C:$C,"2",Sentences!$G:$G,"yanlış ve anlamsız / непонятно") -> 0
A15: 3 | B15: =COUNTIFS(Sentences!$C:$C,"3",Sentences!$G:$G,"doğru / правильно") -> 23 | C15: =COUNTIFS(Sentences!$C:$C,"3",Sentences!$G:$G,"yanlış ama anlaşılır / понятно") -> 19 | D15: =COUNTIFS(Sentences!$C:$C,"3",Sentences!$G:$G,"yanlış ve anlamsız / непонятно") -> 0
A16: 4 | B16: =COUNTIFS(Sentences!$C:$C,"4",Sentences!$G:$G,"doğru / правильно") -> 19 | C16: =COUNTIFS(Sentences!$C:$C,"4",Sentences!$G:$G,"yanlış ama anlaşılır / понятно") -> 24 | D16: =COUNTIFS(Sentences!$C:$C,"4",Sentences!$G:$G,"yanlış ve anlamsız / непонятно") -> 0
A17: 5 | B17: =COUNTIFS(Sentences!$C:$C,"5",Sentences!$G:$G,"doğru / правильно") -> 27 | C17: =COUNTIFS(Sentences!$C:$C,"5",Sentences!$G:$G,"yanlış ama anlaşılır / понятно") -> 12 | D17: =COUNTIFS(Sentences!$C:$C,"5",Sentences!$G:$G,"yanlış ve anlamsız / непонятно") -> 1
A19: Language compliance by tool / Araca göre dil uyumu / Соответствие языку по инструментам
A20: Tool Araç Инструмент | B20: TAM Full Tam Полное | C20: KISMEN Partial Kısmen Частичное | D20: UYUM_YOK None Uyum yok Нет
A21: 1 | B21: =COUNTIFS(Responses!$C:$C,"1",Responses!$I:$I,"tam / полное") -> 0 | C21: =COUNTIFS(Responses!$C:$C,"1",Responses!$I:$I,"kısmen / частичное") -> 7 | D21: =COUNTIFS(Responses!$C:$C,"1",Responses!$I:$I,"uyum yok / нет") -> 0
A22: 2 | B22: =COUNTIFS(Responses!$C:$C,"2",Responses!$I:$I,"tam / полное") -> 4 | C22: =COUNTIFS(Responses!$C:$C,"2",Responses!$I:$I,"kısmen / частичное") -> 3 | D22: =COUNTIFS(Responses!$C:$C,"2",Responses!$I:$I,"uyum yok / нет") -> 0
A23: 3 | B23: =COUNTIFS(Responses!$C:$C,"3",Responses!$I:$I,"tam / полное") -> 2 | C23: =COUNTIFS(Responses!$C:$C,"3",Responses!$I:$I,"kısmen / частичное") -> 5 | D23: =COUNTIFS(Responses!$C:$C,"3",Responses!$I:$I,"uyum yok / нет") -> 0
A24: 4 | B24: =COUNTIFS(Responses!$C:$C,"4",Responses!$I:$I,"tam / полное") -> 0 | C24: =COUNTIFS(Responses!$C:$C,"4",Responses!$I:$I,"kısmen / частичное") -> 6 | D24: =COUNTIFS(Responses!$C:$C,"4",Responses!$I:$I,"uyum yok / нет") -> 1
A25: 5 | B25: =COUNTIFS(Responses!$C:$C,"5",Responses!$I:$I,"tam / полное") -> 0 | C25: =COUNTIFS(Responses!$C:$C,"5",Responses!$I:$I,"kısmen / частичное") -> 7 | D25: =COUNTIFS(Responses!$C:$C,"5",Responses!$I:$I,"uyum yok / нет") -> 0
A27: Semantic adequacy by tool / Araca göre semantik yeterlik / Семантическая адекватность по инструментам
A28: Tool Araç Инструмент | B28: KARSILADI Met Karşıladı Отвечает | C28: KISMEN_KARSILADI Partial Kısmen karşıladı Частично | D28: ALAKASIZ Unrelated Alakasız Не по теме
A29: 1 | B29: =COUNTIFS(Responses!$C:$C,"1",Responses!$J:$J,"karşıladı / отвечает") -> 3 | C29: =COUNTIFS(Responses!$C:$C,"1",Responses!$J:$J,"kısmen karşıladı / частично") -> 3 | D29: =COUNTIFS(Responses!$C:$C,"1",Responses!$J:$J,"alakasız / не по теме") -> 1
A30: 2 | B30: =COUNTIFS(Responses!$C:$C,"2",Responses!$J:$J,"karşıladı / отвечает") -> 7 | C30: =COUNTIFS(Responses!$C:$C,"2",Responses!$J:$J,"kısmen karşıladı / частично") -> 0 | D30: =COUNTIFS(Responses!$C:$C,"2",Responses!$J:$J,"alakasız / не по теме") -> 0
A31: 3 | B31: =COUNTIFS(Responses!$C:$C,"3",Responses!$J:$J,"karşıladı / отвечает") -> 6 | C31: =COUNTIFS(Responses!$C:$C,"3",Responses!$J:$J,"kısmen karşıladı / частично") -> 1 | D31: =COUNTIFS(Responses!$C:$C,"3",Responses!$J:$J,"alakasız / не по теме") -> 0
A32: 4 | B32: =COUNTIFS(Responses!$C:$C,"4",Responses!$J:$J,"karşıladı / отвечает") -> 5 | C32: =COUNTIFS(Responses!$C:$C,"4",Responses!$J:$J,"kısmen karşıladı / частично") -> 1 | D32: =COUNTIFS(Responses!$C:$C,"4",Responses!$J:$J,"alakasız / не по теме") -> 1
A33: 5 | B33: =COUNTIFS(Responses!$C:$C,"5",Responses!$J:$J,"karşıladı / отвечает") -> 6 | C33: =COUNTIFS(Responses!$C:$C,"5",Responses!$J:$J,"kısmen karşıladı / частично") -> 0 | D33: =COUNTIFS(Responses!$C:$C,"5",Responses!$J:$J,"alakasız / не по теме") -> 1
A35: Consistency check / Tutarlılık denetimi / Проверка согласованности
A36: Sentences where "Correct words" (L) is negative -- should be 0 (shows whether a pasted value bypassed the entry-time guard) "Doğru sözcük" (L) negatif olan cümleler -- 0 olmalı (yapıştırma yoluyla giriş sırasındaki korumanın aşılıp aşılmadığını gösterir) Предложения, где «Правильные слова» (L) отрицательны — должно быть 0 (показывает, была ли обойдена защита при вводе вставкой значения) | B36: =COUNTIF(Sentences!$L:$L,"<0") -> 0
A38: Question 7 verdict by tool / Araca göre 7. soru yargısı / Оценка вопроса 7 по инструментам
A39: Tool Araç Инструмент | B39: FARKI_DOGRU_BULDU processed both texts iki metni de işlemiştir обработал оба текста | C39: FARK_YOK_DEDI did not align the texts metinleri hizalamamıştır не сопоставил тексты | D39: FARKI_YANLIS_BULDU invented a difference that is not there (hallucination) olmayan bir fark uydurmuştur (halüsinasyon) придумал несуществующее различие (галлюцинация)
A40: 1 | B40: =COUNTIFS(Responses!$C:$C,"1",Responses!$L:$L,"iki metni de işlemiştir / обработал оба текста") -> 0 | C40: =COUNTIFS(Responses!$C:$C,"1",Responses!$L:$L,"metinleri hizalamamıştır / не сопоставил тексты") -> 0 | D40: =COUNTIFS(Responses!$C:$C,"1",Responses!$L:$L,"olmayan bir fark uydurmuştur (halüsinasyon) / придумал несуществующее различие (галлюцинация)") -> 1
A41: 2 | B41: =COUNTIFS(Responses!$C:$C,"2",Responses!$L:$L,"iki metni de işlemiştir / обработал оба текста") -> 1 | C41: =COUNTIFS(Responses!$C:$C,"2",Responses!$L:$L,"metinleri hizalamamıştır / не сопоставил тексты") -> 0 | D41: =COUNTIFS(Responses!$C:$C,"2",Responses!$L:$L,"olmayan bir fark uydurmuştur (halüsinasyon) / придумал несуществующее различие (галлюцинация)") -> 0
A42: 3 | B42: =COUNTIFS(Responses!$C:$C,"3",Responses!$L:$L,"iki metni de işlemiştir / обработал оба текста") -> 1 | C42: =COUNTIFS(Responses!$C:$C,"3",Responses!$L:$L,"metinleri hizalamamıştır / не сопоставил тексты") -> 0 | D42: =COUNTIFS(Responses!$C:$C,"3",Responses!$L:$L,"olmayan bir fark uydurmuştur (halüsinasyon) / придумал несуществующее различие (галлюцинация)") -> 0
A43: 4 | B43: =COUNTIFS(Responses!$C:$C,"4",Responses!$L:$L,"iki metni de işlemiştir / обработал оба текста") -> 0 | C43: =COUNTIFS(Responses!$C:$C,"4",Responses!$L:$L,"metinleri hizalamamıştır / не сопоставил тексты") -> 1 | D43: =COUNTIFS(Responses!$C:$C,"4",Responses!$L:$L,"olmayan bir fark uydurmuştur (halüsinasyon) / придумал несуществующее различие (галлюцинация)") -> 0
A44: 5 | B44: =COUNTIFS(Responses!$C:$C,"5",Responses!$L:$L,"iki metni de işlemiştir / обработал оба текста") -> 1 | C44: =COUNTIFS(Responses!$C:$C,"5",Responses!$L:$L,"metinleri hizalamamıştır / не сопоставил тексты") -> 0 | D44: =COUNTIFS(Responses!$C:$C,"5",Responses!$L:$L,"olmayan bir fark uydurmuştur (halüsinasyon) / придумал несуществующее различие (галлюцинация)") -> 0
A46: Contact languages by tool / Araca göre temas dilleri / Языки контакта по инструментам
A47: Tool Araç Инструмент | B47: KBD Kabardian Kabartayca Кабардинский | C47: RUS Russian Rusça Русский | D47: TUR Turkish Türkçe Турецкий | E47: ENG English İngilizce Английский | F47: OTHER Other Diğer Прочие | G47: Total Toplam Всего
...
